Workbook

Sheet 개요
A1: SK하이닉스 ADR–레버리지 ETF NAV 괴리거래 모델
A2: 기준일 2026-07-08 | 성격: 델타 중립형 통계적 차익거래 (상호 전환 불가 → 무위험 차익 아님)
A4: 핵심 전략 매트릭스
A5: ADR 상태 | B5: ADR 포지션 | C5: 국내 ETF 포지션
A6: ADR가 본주 대비 고평가 | B6: ADR 공매도 | C6: 레버리지 ETF 매수 (금액 = 명목/β_L)
A7: ADR가 본주 대비 저평가 | B7: ADR 매수 | C7: 인버스2X ETF 매수 (금액 = 명목/|β_I|)
A9: · ADR 10주 = 본주 1주 (Source: Reuters, 2026-07-06, SK Hynix $28bn US listing)
A10: · 양 전략 모두 원·달러 환헤지 필수 (ADR 달러 표시 ↔ ETF 원화 표시)
A11: · 1단계 권장: 전략② (ADR 저평가 시 ADR 매수 + SOL 인버스2X 매수 — 공매도·대차 불필요)
A13: 시트 구성
A14: 대시보드 | B14: 시장 데이터 입력 → ADR 프리미엄·ETF 괴리·진입 신호 자동 판정
A15: 포지션계산 | B15: 베타 조정 델타 중립 포지션 규모 + 시나리오 P&L
A16: 개장가예측 | B16: 야간 ADR → 다음날 시초가·예상 NAV 계산, 개장 후 괴리 판정
A17: 진입청산규칙 | B17: 진입 6개 조건·청산 5개 조건 체크리스트 (대시보드 연동 자동 판정)
A18: ETF후보 | B18: 레버리지 7종 + 인버스2X 후보와 선정 기준
A19: 리스크 | B19: 5대 리스크와 대응
A21: 색상 범례
A22: 파란 글씨 = 직접 입력값
A23: 검정 글씨 = 수식(자동 계산)
A24: 초록 글씨 = 다른 시트 연동값
A25: 노란 배경 = 데이터 축적 후 갱신 필요한 핵심 가정
A27: ※ 본 파일은 분석·교육용 모델이며 투자 권유가 아닙니다. 실거래 전 대차 가능 여부·비용·규제를 반드시 확인하십시오.

Sheet 대시보드
A1: ① 신호 대시보드
A3: 시장 데이터 입력
A4: ADR 가격 ($) | B4: 160
A5: 원/달러 환율 (원/$) | B5: 1500
A6: SK하이닉스 본주가격 (원) | B6: 2300000
A7: ADR 전환비율 (ADR주 수/본주 1주) | B7: 10
A8: 레버리지 ETF 시장가격 (원) | B8: 41500
A9: 레버리지 ETF iNAV (원) | B9: 41800
A10: 인버스2X ETF 시장가격 (원) | B10: 4150
A11: 인버스2X ETF iNAV (원) | B11: 4190
A13: 파라미터
A14: 레버리지 ETF 실측베타 β_L | B14: 1.88
A15: 인버스 ETF 실측베타 β_I | B15: -1.88
A16: ADR 포지션 명목금액 (원) | B16: 100000000
A17: 총거래비용 (수수료+세금+대차료+환헤지) | B17: 0.01
A18: 안전마진 | B18: 0.005
A19: 괴리율 평균 μ (과거) | B19: 0
A20: 괴리율 표준편차 σ (과거) | B20: 0.016
A22: 계산 결과
A23: ADR 환산 본주가격 (원) = 비율×ADR×환율 | B23: =B7*B4*B5 -> 2400000
A24: ADR 프리미엄 = 환산가/본주 − 1 | B24: =B23/B6-1 -> 0.043478261
A25: 레버리지 ETF 괴리율 = 시장가/iNAV − 1 | B25: =B8/B9-1 -> -0.0071770335
A26: 인버스 ETF 괴리율 = 시장가/iNAV − 1 | B26: =B10/B11-1 -> -0.0095465394
A27: 진입기준 = MAX(2.5σ, 총비용+안전마진) | B27: =MAX(2.5*B20,B17+B18) -> 0.04
A28: 표준화 괴리 Z = (프리미엄−μ)/σ | B28: =(B24-B19)/B20 -> 2.7173913
A29: 전략① 유효엣지 = 프리미엄 − 레버리지 괴리 | B29: =B24-B25 -> 0.050655294
A30: 전략② 유효엣지 = −프리미엄 − 인버스 괴리 | B30: =-B24-B26 -> -0.033931721
A32: 신호 판정
A33: 판정 | B33: =IF(AND(B24>=B27,B25<=0),"전략① 진입: ADR 공매도 + 레버리지 ETF 매수 + 환헤지",IF(AND(B24<=-B27,B26<=0),"전략② 진입: ADR 매수 + 인버스2X ETF 매수 + 환헤지",IF(B24>=B27,"보류: ADR 고평가이나 레버리지 ETF도 고평가 → 엣지 축소",IF(B24<=-B27,"보류: ADR 저평가이나 인버스 ETF 고평가 → 엣지 축소","대기: 괴리 부족")))) -> 전략① 진입: ADR 공매도 + 레버리지 ETF 매수 + 환헤지
A34: 예상 순이익률 = 해당 전략 엣지 − 총비용 | B34: =IF(B24>=0,B29,B30)-B17 -> 0.040655294
A35: 수익성 체크 (순이익 ≥ 총비용×2) | B35: =IF(B34>=2*B17,"충족","미충족") -> 충족
A37: · 최적 진입 ①: ADR 고평가 + 레버리지 ETF가 NAV 대비 저평가(괴리 ≤ 0)
A38: · 최적 진입 ②: ADR 저평가 + 인버스2X ETF가 NAV 대비 저평가(괴리 ≤ 0)
A39: · 회피: ADR 고평가인데 레버리지 ETF도 크게 고평가 — 헤지를 비싸게 사며 엣지 축소

Sheet 포지션계산
A1: ② 포지션 계산기 (베타 조정 델타 중립)
A3: 공통 파라미터 (대시보드 연동)
A4: ADR 명목금액 (원) | B4: =대시보드!B16 -> 100000000
A5: ADR 프리미엄 (현재) | B5: =대시보드!B24 -> 0.043478261
A6: 원/달러 환율 | B6: =대시보드!B5 -> 1500
A7: 레버리지 실측베타 β_L | B7: =대시보드!B14 -> 1.88
A8: 인버스 실측베타 β_I | B8: =대시보드!B15 -> -1.88
A9: 청산 목표 괴리 (절댓값 가정) | B9: 0.01
A11: 전략① ADR 고평가 → ADR 공매도 + 레버리지 ETF 매수 + 환헤지
A12: ADR 공매도 명목 (원) | B12: =B4 -> 100000000
A13: 레버리지 ETF 매수금액 (원) = 명목/β_L | B13: =B4/B7 -> 53191489
A14: 레버리지 ETF 현재가 (원) | B14: =대시보드!B8 -> 41500
A15: ETF 매수 주수 (주) | B15: =ROUND(B13/B14,0) -> 1282
A16: 환헤지 명목 ($) — 달러 매도 | B16: =B12/B6 -> 66666.667
A17: 괴리 축소 기대수익 (원) = 명목×(진입P−목표P) | B17: =B12*(B5-B9) -> 3347826.1
A19: 전략② ADR 저평가 → ADR 매수 + 인버스2X ETF 매수 + 환헤지
A20: ADR 매수 명목 (원) | B20: =B4 -> 100000000
A21: 인버스 ETF 매수금액 (원) = 명목/|β_I| | B21: =B4/ABS(B8) -> 53191489
A22: 인버스 ETF 현재가 (원) | B22: =대시보드!B10 -> 4150
A23: ETF 매수 주수 (주) | B23: =ROUND(B21/B22,0) -> 12817
A24: 환헤지 명목 ($) — 달러 매수 예약 | B24: =B20/B6 -> 66666.667
A25: 괴리 축소 기대수익 (원) = 명목×(−목표P−진입P) | B25: =B20*(-B9-B5) -> -5347826.1
A27: ※ ETF 투자금은 50% 고정이 아니라 실측 베타로 나눠 결정 (예: 1억/1.88 = 5,319만원)
A29: 시나리오 P&L — 전략① (본주 수익률별)
A30: 본주 수익률 | B30: ADR측 손익 (원) | C30: ETF측 손익 (원) | D30: 방향성 순손익 (원) | E30: 괴리축소 손익 (원) | F30: 총손익 (원)
A31: -0.1 | B31: =-$B$12*A31 -> 10000000 | C31: =$B$13*$B$7*A31 -> -10000000 | D31: =B31+C31 -> 0 | E31: =$B$17 -> 3347826.1 | F31: =D31+E31 -> 3347826.1
A32: -0.05 | B32: =-$B$12*A32 -> 5000000 | C32: =$B$13*$B$7*A32 -> -5000000 | D32: =B32+C32 -> 0 | E32: =$B$17 -> 3347826.1 | F32: =D32+E32 -> 3347826.1
A33: -0.03 | B33: =-$B$12*A33 -> 3000000 | C33: =$B$13*$B$7*A33 -> -3000000 | D33: =B33+C33 -> 0 | E33: =$B$17 -> 3347826.1 | F33: =D33+E33 -> 3347826.1
A34: 0 | B34: =-$B$12*A34 -> 0 | C34: =$B$13*$B$7*A34 -> 0 | D34: =B34+C34 -> 0 | E34: =$B$17 -> 3347826.1 | F34: =D34+E34 -> 3347826.1
A35: 0.03 | B35: =-$B$12*A35 -> -3000000 | C35: =$B$13*$B$7*A35 -> 3000000 | D35: =B35+C35 -> 0 | E35: =$B$17 -> 3347826.1 | F35: =D35+E35 -> 3347826.1
A36: 0.05 | B36: =-$B$12*A36 -> -5000000 | C36: =$B$13*$B$7*A36 -> 5000000 | D36: =B36+C36 -> 0 | E36: =$B$17 -> 3347826.1 | F36: =D36+E36 -> 3347826.1
A37: 0.1 | B37: =-$B$12*A37 -> -10000000 | C37: =$B$13*$B$7*A37 -> 10000000 | D37: =B37+C37 -> 0 | E37: =$B$17 -> 3347826.1 | F37: =D37+E37 -> 3347826.1
A39: 시나리오 P&L — 전략② (본주 수익률별)
A40: 본주 수익률 | B40: ADR측 손익 (원) | C40: ETF측 손익 (원) | D40: 방향성 순손익 (원) | E40: 괴리축소 손익 (원) | F40: 총손익 (원)
A41: -0.1 | B41: =$B$20*A41 -> -10000000 | C41: =$B$21*$B$8*A41 -> 10000000 | D41: =B41+C41 -> 0 | E41: =$B$25 -> -5347826.1 | F41: =D41+E41 -> -5347826.1
A42: -0.05 | B42: =$B$20*A42 -> -5000000 | C42: =$B$21*$B$8*A42 -> 5000000 | D42: =B42+C42 -> 0 | E42: =$B$25 -> -5347826.1 | F42: =D42+E42 -> -5347826.1
A43: -0.03 | B43: =$B$20*A43 -> -3000000 | C43: =$B$21*$B$8*A43 -> 3000000 | D43: =B43+C43 -> 0 | E43: =$B$25 -> -5347826.1 | F43: =D43+E43 -> -5347826.1
A44: 0 | B44: =$B$20*A44 -> 0 | C44: =$B$21*$B$8*A44 -> 0 | D44: =B44+C44 -> 0 | E44: =$B$25 -> -5347826.1 | F44: =D44+E44 -> -5347826.1
A45: 0.03 | B45: =$B$20*A45 -> 3000000 | C45: =$B$21*$B$8*A45 -> -3000000 | D45: =B45+C45 -> 0 | E45: =$B$25 -> -5347826.1 | F45: =D45+E45 -> -5347826.1
A46: 0.05 | B46: =$B$20*A46 -> 5000000 | C46: =$B$21*$B$8*A46 -> -5000000 | D46: =B46+C46 -> 0 | E46: =$B$25 -> -5347826.1 | F46: =D46+E46 -> -5347826.1
...

Sheet 개장가예측
A1: ③ 야간 ADR → 개장가·NAV 예측
A3: 입력 (미국장 마감 후)
A4: 전일 본주 종가 (원) | B4: 2300000
A5: 야간 ADR 종가 ($) | B5: 161
A6: 원/달러 환율 (원/$) | B6: 1500
A7: ADR 전환비율 | B7: =대시보드!B7 -> 10
A8: 전일 레버리지 ETF NAV (원) | B8: 40000
A9: 전일 인버스 ETF NAV (원) | B9: 4000
A10: 예상 선물 수익률 (인버스용) | B10: =B15 -> 0.05
A11: 시초가 괴리 판정 기준 (±) | B11: 0.01
A13: 계산
A14: 예상 본주 시초가 (원) = 비율×ADR×환율 | B14: =B7*B5*B6 -> 2415000
A15: 예상 본주 수익률 = 예상시초가/전일종가 − 1 | B15: =B14/B4-1 -> 0.05
A16: 예상 레버리지 ETF NAV = NAV×(1+2r) | B16: =B8*(1+2*B15) -> 44000
A17: 예상 인버스 ETF NAV = NAV×(1−2r_선물) | B17: =B9*(1-2*B10) -> 3600
A19: 개장 후 판정
A20: 실제 레버리지 시초가 (원) | B20: 41500
A21: 실제 인버스 시초가 (원) | B21: 3600
A22: 레버리지 시초가 괴리 = 실제/예상NAV − 1 | B22: =B20/B16-1 -> -0.056818182
A23: 인버스 시초가 괴리 = 실제/예상NAV − 1 | B23: =B21/B17-1 -> 0
A24: 레버리지 판정 | B24: =IF(B22<=-B11,"저평가 → 매수 후보",IF(B22>=B11,"고평가·과열 → 매수 회피","중립")) -> 저평가 → 매수 후보
A25: 인버스 판정 | B25: =IF(B23<=-B11,"저평가 → 매수 후보",IF(B23>=B11,"고평가·과열 → 매수 회피","중립")) -> 중립
A27: ※ 미국 마감~한국 개장 사이 새 뉴스 발생 가능 → 엄밀한 차익거래가 아닌 개장가 예측·괴리 회귀 전략.
A28: ※ 인버스2X는 SK하이닉스 선물지수 추종 (Source: 삼성증권 리서치, 2026-05).

Sheet 진입청산규칙
A1: ④ 진입·청산 규칙
A3: 현재 진입기준 = MAX(2.5σ, 총비용+안전마진) | B3: =대시보드!B27 -> 0.04
A4: ※ 신규 상장 직후 데이터 부족 → 초기에는 ADR 환산 괴리 4~5% 이상에서만 보수적으로 진입 권장.
A6: 진입 체크리스트
A7: 항목 | B7: 기준 | C7: 현재값/입력 | D7: 판정
A8: ADR 환산 괴리율 (절댓값) | B8: ≥ 진입기준 | C8: =ABS(대시보드!B24) -> 0.043478261 | D8: =IF(C8>=대시보드!B27,"충족","미충족") -> 충족
A9: 유효 엣지 (ETF 괴리 반영 순괴리) | B9: ≥ 3% | C9: =MAX(대시보드!B29,대시보드!B30) -> 0.050655294 | D9: =IF(C9>=0.03,"충족","미충족") -> 충족
A10: 예상 순이익 (엣지 − 총비용) | B10: ≥ 총비용 × 2 | C10: =대시보드!B34 -> 0.040655294 | D10: =IF(C10>=2*대시보드!B17,"충족","미충족") -> 충족
A11: ADR 대차 가능 (전략① 필수) | B11: Y / N 입력 | C11: Y | D11: =IF(C11="Y","충족","확인필요") -> 충족
A12: ETF 호가 스프레드 정상 | B12: Y / N 입력 | C12: Y | D12: =IF(C12="Y","충족","확인필요") -> 충족
A13: 환헤지 체결 준비 완료 | B13: Y / N 입력 | C13: Y | D13: =IF(C13="Y","충족","확인필요") -> 충족
A14: 종합 판정 | B14: 6개 항목 전부 충족 시 진입 | C14: =COUNTIF(D8:D13,"충족") -> 6 | D14: =IF(C14=6,"진입 가능","진입 불가") -> 진입 가능
A16: 청산 기준 (하나라도 해당 시 청산)
A17: 항목 | B17: 기준 | C17: 현재값 | D17: 판정
A18: ADR–본주 괴리 축소 | B18: 절댓값 ≤ 1% | C18: =ABS(대시보드!B24) -> 0.043478261 | D18: =IF(C18<=0.01,"청산 검토","유지") -> 유지
A19: 표준화 괴리 |Z| | B19: ≤ 0.5 | C19: =ABS(대시보드!B28) -> 2.7173913 | D19: =IF(C19<=0.5,"청산 검토","유지") -> 유지
A20: 최대 보유기간 | B20: 1~3거래일 | C20: 수동 관리 | D20: —
A21: 실측 베타 이탈 | B21: 목표 대비 큰 이탈 시 | C21: 수동 관리 | D21: —
A22: 대차료 급등 / 주식 반환(리콜) 요청 | B22: 발생 즉시 | C22: 수동 관리 | D22: —

Sheet ETF후보
A1: ⑤ 국내 헤지 ETF 후보
A3: 상품 (브랜드) | B3: 운용사 | C3: 유형 | D3: 구조 | E3: 종목코드 | F3: 평균 거래대금 | G3: 호가 스프레드 | H3: 실측 β
A4: KODEX SK하이닉스 레버리지 | B4: 삼성자산운용 | C4: 레버리지 (2X) | D4: 현물·선물 혼합 또는 선물 (확인 필요)
A5: TIGER SK하이닉스 레버리지 | B5: 미래에셋자산운용 | C5: 레버리지 (2X) | D5: 현물·선물 혼합 또는 선물 (확인 필요)
A6: ACE SK하이닉스 레버리지 | B6: 한국투자신탁운용 | C6: 레버리지 (2X) | D6: 현물·선물 혼합 또는 선물 (확인 필요)
A7: RISE SK하이닉스 레버리지 | B7: KB자산운용 | C7: 레버리지 (2X) | D7: 현물·선물 혼합 또는 선물 (확인 필요)
A8: SOL SK하이닉스 레버리지 | B8: 신한자산운용 | C8: 레버리지 (2X) | D8: 현물·선물 혼합 또는 선물 (확인 필요)
A9: 1Q SK하이닉스 레버리지 | B9: 하나자산운용 | C9: 레버리지 (2X) | D9: 현물·선물 혼합 또는 선물 (확인 필요)
A10: KIWOOM SK하이닉스 레버리지 | B10: 키움투자자산운용 | C10: 레버리지 (2X) | D10: 현물·선물 혼합 또는 선물 (확인 필요)
A11: SOL SK하이닉스선물단일종목인버스2X | B11: 신한자산운용 | C11: 인버스 (-2X) | D11: SK하이닉스 선물지수 추종
A13: Source: 삼성증권 리서치 (2026-05) — 상장 신청 기준 레버리지 7종 + SOL 인버스2X.
A14: Source: KRX KIND (2026-06-22) — KODEX·TIGER 레버리지, SOL 인버스2X 거래량 상대적 우위. 유동성은 매일 변동 → 실시간 호가·iNAV 기준 선택.
A15: 노란 칸은 거래 시점에 조회하여 입력 (종목코드·거래대금·스프레드·실측 베타).
A17: 선정 기준 (우선순위)
A18: 1. 매수·매도 호가 스프레드
A19: 2. 호가 잔량
A20: 3. 시장가격–iNAV 괴리
A21: 4. 실제 추종 베타
A22: 5. 거래대금
A23: 6. 선물형 vs 현물·선물 혼합형
A25: ※ 단기 차익거래에서는 보수(수수료율) 차이보다 체결 슬리피지·추적오차가 더 중요.

Sheet 리스크
A1: ⑥ 5대 리스크와 대응
A3: 리스크 | B3: 내용 | C3: 영향 | D3: 대응
A4: ① 거래시간 불일치 | B4: 한국 ETF와 미국 ADR 정규장이 겹치지 않음 | C4: 한쪽 먼저 체결 후 다른 시장 개장까지 가격위험 부담 | D4: 포지션 축소, 야간 파생·프리마켓 참고, 부분 분할 체결
A5: ② 일일 재설정 | B5: 레버리지·인버스2X는 누적이 아닌 매일 수익률의 ±2배 추종 | C5: 다일 보유 시 변동성 손실·복리효과로 헤지비율 이탈 | D5: 보유 1~3거래일 제한, 일일 헤지비율 점검·리밸런싱
A6: ③ 현물–선물 차이 | B6: SOL 인버스2X는 선물지수 추종: 베이시스·만기·롤오버·가격제한 | C6: 현물 기준 예측과 추적 오차 발생 | D6: 베이시스 모니터링, 선물 만기 주간 진입 회피
A7: ④ 환율 | B7: ADR는 달러, ETF는 원화 표시 | C7: 프리미엄 축소돼도 환율 급변으로 손실 가능 | D7: 선물환·달러선물 등으로 환헤지 필수
A8: ⑤ 괴리 장기화 | B8: ADR–본주 전환이 신청·심사·승인 방식일 가능성 (Source: 인베스트조선 2026-07-08) | C8: 프리미엄/할인율이 예상보다 오래 유지 | D8: 손절 기준·보유기간 상한 설정, 포지션 규모 제한
A10: ADR 수익률 분해: ADR수익률 ≈ 본주 주가수익률 + 환율수익률 + ADR 프리미엄 변화
A12: ※ 본 모델은 정보 제공용이며 투자 권유가 아닙니다. 공매도·대차·환헤지 관련 규제와 비용은 거래 전 필수 확인.
